<?xml version="1.0"?>
<robot xmlns:xacro="http://www.ros.org/wiki/xacro">


  <xacro:property name="base_length"    value="0.40"/>  <!-- x -->
  <xacro:property name="base_width"     value="0.30"/>  <!-- y -->
  <xacro:property name="base_height"    value="0.15"/>  <!-- z -->

  <xacro:property name="wheel_radius"   value="0.08"/>
  <xacro:property name="wheel_length"   value="0.04"/>

  <xacro:property name="caster_radius"  value="0.03"/>

  <xacro:property name="lidar_radius"   value="0.04"/>
  <xacro:property name="lidar_length"   value="0.05"/>


  <link name="base_footprint"/>

  <joint name="base_footprint_joint" type="fixed">
    <parent link="base_footprint"/>
    <child  link="base_link"/>
    <origin xyz="0 0 ${wheel_radius}" rpy="0 0 0"/>
  </joint>


  <link name="base_link">
    <visual>
      <geometry>
        <box size="${base_length} ${base_width} ${base_height}"/>
      </geometry>
      <origin xyz="0 0 ${base_height/2.0}" rpy="0 0 0"/>
      <material name="blue"/>
    </visual>
    <collision>
      <geometry>
        <box size="${base_length} ${base_width} ${base_height}"/>
      </geometry>
      <origin xyz="0 0 ${base_height/2.0}" rpy="0 0 0"/>
    </collision>
    <xacro:box_inertia
      m="5.0"
      l="${base_length}" w="${base_width}" h="${base_height}"
      xyz="0 0 ${base_height/2.0}"
      rpy="0 0 0"/>
  </link>


  <xacro:macro name="wheel_link" params="name">
    <link name="${name}">
      <visual>
        <geometry>
          <cylinder radius="${wheel_radius}" length="${wheel_length}"/>
        </geometry>
        <origin xyz="0 0 0" rpy="${pi/2.0} 0 0"/>
        <material name="black"/>
      </visual>
      <collision>
        <geometry>
          <cylinder radius="${wheel_radius}" length="${wheel_length}"/>
        </geometry>
        <origin xyz="0 0 0" rpy="${pi/2.0} 0 0"/>
      </collision>
      <xacro:cylinder_inertia
        m="0.5"
        r="${wheel_radius}" h="${wheel_length}"
        xyz="0 0 0"
        rpy="${pi/2.0} 0 0"/>
    </link>
  </xacro:macro>


  <xacro:wheel_link name="left_wheel_link"/>
  <joint name="base_left_wheel_joint" type="continuous">
    <parent link="base_link"/>
    <child  link="left_wheel_link"/>
    <origin xyz="${-base_length/4.0} ${(base_width/2.0) + (wheel_length/2.0)} 0" rpy="0 0 0"/>
    <axis xyz="0 1 0"/>
  </joint>


  <xacro:wheel_link name="right_wheel_link"/>
  <joint name="base_right_wheel_joint" type="continuous">
    <parent link="base_link"/>
    <child  link="right_wheel_link"/>
    <origin xyz="${-base_length/4.0} ${-(base_width/2.0) - (wheel_length/2.0)} 0" rpy="0 0 0"/>
    <axis xyz="0 1 0"/>
  </joint>


  <link name="caster_wheel_link">
    <visual>
      <geometry>
        <sphere radius="${caster_radius}"/>
      </geometry>
      <origin xyz="0 0 0" rpy="0 0 0"/>
      <material name="gray"/>
    </visual>
    <collision>
      <geometry>
        <sphere radius="${caster_radius}"/>
      </geometry>
      <origin xyz="0 0 0" rpy="0 0 0"/>
    </collision>
    <xacro:sphere_inertia
      m="0.2"
      r="${caster_radius}"
      xyz="0 0 0"
      rpy="0 0 0"/>
  </link>

  <joint name="caster_wheel_joint" type="fixed">
    <parent link="base_link"/>
    <child  link="caster_wheel_link"/>
    <!-- Place at front, touching ground: base_height=0 plane, drop by wheel_radius-caster_radius -->
    <origin xyz="${base_length/3.0} 0 ${-(wheel_radius - caster_radius)}" rpy="0 0 0"/>
  </joint>

  <!-- ========== LIDAR SENSOR LINK ========== -->
  <link name="lidar_link">
    <visual>
      <geometry>
        <cylinder radius="${lidar_radius}" length="${lidar_length}"/>
      </geometry>
      <origin xyz="0 0 0" rpy="0 0 0"/>
      <material name="red"/>
    </visual>
    <collision>
      <geometry>
        <cylinder radius="${lidar_radius}" length="${lidar_length}"/>
      </geometry>
      <origin xyz="0 0 0" rpy="0 0 0"/>
    </collision>
    <xacro:cylinder_inertia
      m="0.1"
      r="${lidar_radius}" h="${lidar_length}"
      xyz="0 0 0"
      rpy="0 0 0"/>
  </link>

  <joint name="lidar_joint" type="fixed">
    <parent link="base_link"/>
    <child  link="lidar_link"/>
    <!-- On top of robot body, centered -->
    <origin xyz="0 0 ${base_height + lidar_length/2.0}" rpy="0 0 0"/>
  </joint>

</robot>
